Workbook

Sheet Cover
B2: TEST REPORT DOCUMENT
A4: Project Name | B4: PharmaChain – Smart Pharmacy Chain Management System | E4: Creator | F4: Tran Hong Phuoc (DE180577)
A5: Project Code | B5: WPE | E5: Issue Date | F5: 17/09/2026
A6: Document Code | B6: Report5_Test_v1.0 | E6: Version | F6: v1.1
A9: Record of change
A10: Effective Date | B10: Version | C10: Change Item | D10: *A,D,M | E10: Change description | F10: Reference
A11: 17/09/2026 | B11: v1.0 | C11: Test Cases & Test Statistics | D11: A | E11: Complete master list of 65 functions across Sprint 1 to Sprint 4 in English matching SRS v1.0 | F11: Report 3 – Software Requirements Specification (SRS)
A12: 01/10/2026 | B12: v1.1 | C12: Test Cases & Statistics (UC-66 to UC-120) | D12: A | E12: Extended full enterprise test suite with UC-66 to UC-120 covering Sprint 5 to Sprint 8 | F12: Report 4 – Software Design Document (SDD v2.0)

Sheet Test Cases
B1: TEST CASE LIST
B3: Project Name | C3: PharmaChain – Smart Pharmacy Chain Management System
B4: Project Code | C4: WDP301
B6: Test Environment Setup Description | C6: 1. Server: Ubuntu Server 24.04 LTS (Docker, K8s, Kafka, Redis, MongoDB) 2. Backend: NestJS Microservices, API Gateway 3. Web & Mobile: React 19, Expo React Native 4. Database: MongoDB 7.0 5. Web Browser: Google Chrome, Microsoft Edge
B8: No | C8: Name | D8: Sheet Name | E8: Description | F8: Pre-Condition
B9: Feature Authentication
B10: 1 | C10: [UC-01] Register account | D10: Authentication | E10: Allows customers to register a new personal account in the system using an email address and password. | F10: Actor 'Customer' authenticated; test environment master data pre-seeded.
B11: 2 | C11: [UC-02] Sign in | D11: Authentication | E11: Allows users to log in to the system using their registered or assigned account credentials. | F11: Actor 'Customer, Pharmacist, Inventory Manager, Admin, Branch Manager' authenticated; test environment master data pre-seeded.
B12: 3 | C12: [UC-03] Verify email | D12: Authentication | E12: Allows customers to confirm the activation code sent to their personal email after successful account registration. | F12: Actor 'Customer, Pharmacist, Branch Manager' authenticated; test environment master data pre-seeded.
B13: 4 | C13: [UC-04] Sign in with Google | D13: Authentication | E13: Allows customers to quickly log in to the online shopping portal using their Google account. | F13: Actor 'Customer' authenticated; test environment master data pre-seeded.
B14: 5 | C14: [UC-05] Recover password | D14: Authentication | E14: Allows staff to send a password recovery request via email when they forget their login credentials. | F14: Actor 'Pharmacist, Inventory Manager, Admin, Branch Manager' authenticated; test environment master data pre-seeded.
B15: 6 | C15: [UC-06] Reset password | D15: Authentication | E15: Allows staff to set a new password via a secure link sent to their recovery email. | F15: Actor 'Pharmacist, Inventory Manager, Admin, Branch Manager' authenticated; test environment master data pre-seeded.
B16: 7 | C16: [UC-07] Sign out | D16: Authentication | E16: Terminates the current session and safely logs out of the system account. | F16: Actor 'Customer, Pharmacist, Inventory Manager, Admin, Branch Manager' authenticated; test environment master data pre-seeded.
B17: 8 | C17: [UC-113] Biometric Mobile Authentication (FaceID/Fingerprint) | D17: Authentication | E17: Integrates iOS FaceID and Android BiometricPrompt for cryptographic token exchange without manual password input. | F17: Device hardware supports biometric sensors; app enrolled.
B18: Feature Online Customer Portal
B19: 9 | C19: [UC-08] Search medicines online | D19: Customer Portal | E19: Browse and search for medicines by name, active ingredient, or medical indication on the online store. | F19: Actor 'Customer' authenticated; test environment master data pre-seeded.
B20: 10 | C20: [UC-09] Add to cart | D20: Customer Portal | E20: Allow customers to save desired pharmaceutical products into their personal cart for later checkout. | F20: Actor 'Customer' authenticated; test environment master data pre-seeded.
B21: 11 | C21: [UC-10] Manage personal cart | D21: Customer Portal | E21: Allow customers to adjust quantities or remove products from their online cart. | F21: Actor 'Customer' authenticated; test environment master data pre-seeded.
B22: 12 | C22: [UC-11] Confirm online order | D22: Customer Portal | E22: Fill in full name, phone number, shipping address, and confirm submission of online order. | F22: Actor 'Customer' authenticated; test environment master data pre-seeded.
B23: 13 | C23: [UC-12] Pay online order | D23: Customer Portal | E23: Complete online payment via bank transfer using dynamic QR code or COD. | F23: Actor 'Customer' authenticated; test environment master data pre-seeded.
B24: 14 | C24: [UC-13] View order history | D24: Customer Portal | E24: View list of past orders, detailed order items, and shipping status. | F24: Actor 'Customer' authenticated; test environment master data pre-seeded.
B25: 15 | C25: [UC-14] View customer profile | D25: Customer Portal | E25: View personal information, accumulated points, and current tier status (Gold, Silver, Bronze...). | F25: Actor 'Customer' authenticated; test environment master data pre-seeded.
B26: 16 | C26: [UC-15] Consult AI via text | D26: Customer Portal | E26: Enter symptom description questions; chatbot automatically analyzes and suggests health guidance & recommended products. | F26: Actor 'Customer' authenticated; test environment master data pre-seeded.
B27: 17 | C27: [UC-16] Consult AI via voice | D27: Customer Portal | E27: Press record button to describe symptoms via voice; AI automatically recognizes speech and converts to text for consultation. | F27: Actor 'Customer' authenticated; test environment master data pre-seeded.
B28: 18 | C28: [UC-80] AI Symptom Consultation Chatbot | D28: Customer Portal | E28: Provides automated interactive AI consultation based on symptoms, recommends OTC relief medicines, and refers to doctors if severe. | F28: Actor 'Customer' authenticated; Gemini AI engine online.
B29: 19 | C29: [UC-81] AI Voice Medicine Search | D29: Customer Portal | E29: Recognizes spoken medical queries in Vietnamese/English, transliterating brand names to generic INN drug names with autocomplete. | F29: Microphone permissions granted; WebSpeech/Whisper API operational.
B30: 20 | C30: [UC-85] Order & Transaction Cancellation | D30: Customer Portal | E30: Processes transaction voiding, order cancellation with mandatory reason codes, stock replenishment rollbacks, and audit logging. | F30: Actor 'Pharmacist, Branch Manager' authenticated; target order in pending/unsettled state.
... B41: 31 | C41: [UC-118] Recurring Medication Auto-Reorder Management | D41: Customer Portal | E41: Schedules monthly repeat prescription dispensations for chronic conditions (hypertension, diabetes), auto-preparing order 3 days in advance. | F41: Customer enrolled in recurring prescription auto-refill plan.
B42: Feature Pharmacist POS Counter Terminal
B43: 32 | C43: [UC-17] Search retail medicines | D43: Pharmacist POS | E43: Quickly search for medicines by name or active ingredient directly on the counter retail screen. | F43: Actor 'Pharmacist' authenticated; test environment master data pre-seeded.
B44: 33 | C44: [UC-18] Add to retail cart | D44: Pharmacist POS | E44: Select medicines from search results and add them to the customer's active retail shopping cart. | F44: Actor 'Pharmacist' authenticated; test environment master data pre-seeded.
B45: 34 | C45: [UC-19] Edit retail cart | D45: Pharmacist POS | E45: Change purchase quantity of each medicine or remove items from the retail cart. | F45: Actor 'Pharmacist' authenticated; test environment master data pre-seeded.
B46: 35 | C46: [UC-20] Suggest substitute medicine | D46: Pharmacist POS | E46: System automatically suggests equivalent substitute medicines (matching active ingredient or therapeutic group) when requested item is out of stock. | F46: Actor 'Pharmacist' authenticated; test environment master data pre-seeded.
B47: 36 | C47: [UC-21] Apply voucher and points | D47: Pharmacist POS | E47: Look up loyalty customer information by phone number to earn reward points or apply discount voucher codes directly to the invoice. | F47: Actor 'Pharmacist' authenticated; test environment master data pre-seeded.
B48: 37 | C48: [UC-22] Scan prescription with AI | D48: Pharmacist POS | E48: Capture/upload doctor prescription photos (single/multi-page). AI Gemini 2.5 Flash analyzes layout, extracts active ingredients/dosages, merges duplicates, matches branch DB & auto-selects nearest FEFO batch to auto-fill cart. | F48: Actor 'Pharmacist' authenticated; test environment master data pre-seeded.
B49: 38 | C49: [UC-23] Check medicine interactions | D49: Pharmacist POS | E49: Select multiple medicines in cart to trigger AI verification for interactions or harmful contraindication warnings. | F49: Actor 'Pharmacist' authenticated; test environment master data pre-seeded.
B50: 39 | C50: [UC-24] Confirm retail payment | D50: Pharmacist POS | E50: Confirm transactions via Cash or Bank Transfer. System automatically deducts branch stock based on FIFO batches and prints invoices. | F50: Actor 'Pharmacist' authenticated; test environment master data pre-seeded.
B51: 40 | C51: [UC-25] Send e-invoice via email | D51: Pharmacist POS | E51: Allows entering customer email at counter to send electronic invoice (e-invoice) directly upon payment completion. | F51: Actor 'Pharmacist' authenticated; test environment master data pre-seeded.
B52: 41 | C52: [UC-26] Create wholesale invoice | D52: Pharmacist POS | E52: Issue wholesale invoices for agency partners, automatically applying tier pricing based on large volume purchases. | F52: Actor 'Pharmacist' authenticated; test environment master data pre-seeded.
B53: 42 | C53: [UC-27] Search return invoice | D53: Pharmacist POS | E53: Search past invoices by customer phone number or invoice code to verify purchase origin prior to executing returns. | F53: Actor 'Pharmacist' authenticated; test environment master data pre-seeded.
...

Sheet Test Statistics
B1: TEST STATISTICS
B3: Project Name | C3: PharmaChain – Smart Pharmacy Chain Management System | E3: Creator | G3: Tran Hong Phuoc (DE180577)
B4: Project Code | C4: WDP301 | E4: Reviewer/Approver | G4: Nguyen Van Nam (DE180564)
B5: Document Code | C5: WDP301_Test Report_v1.2 | E5: Issue Date | G5: 07/10/2026
B6: Notes | C6: Release includes all 8 Modules across Sprints 1 to 8 (120 UCs / 360 TCs)
B10: No | C10: Module code | D10: Passed | E10: Failed | F10: Pending | G10: N/A | H10: Number of test cases
B11: 1 | C11: Feature Authentication | D11: ='FE-01_Authentication'!B6 | E11: ='FE-01_Authentication'!C6 | F11: ='FE-01_Authentication'!D6 | G11: ='FE-01_Authentication'!E6 | H11: ='FE-01_Authentication'!B4
B12: 2 | C12: Feature Online Customer Portal | D12: ='FE-02_Customer Portal'!B6 | E12: ='FE-02_Customer Portal'!C6 | F12: ='FE-02_Customer Portal'!D6 | G12: ='FE-02_Customer Portal'!E6 | H12: ='FE-02_Customer Portal'!B4
B13: 3 | C13: Feature Pharmacist POS Counter Terminal | D13: ='FE-03_Pharmacist POS'!B6 | E13: ='FE-03_Pharmacist POS'!C6 | F13: ='FE-03_Pharmacist POS'!D6 | G13: ='FE-03_Pharmacist POS'!E6 | H13: ='FE-03_Pharmacist POS'!B4
B14: 4 | C14: Feature Central Warehouse & FEFO Inventory | D14: ='FE-04_Central Warehouse'!B6 | E14: ='FE-04_Central Warehouse'!C6 | F14: ='FE-04_Central Warehouse'!D6 | G14: ='FE-04_Central Warehouse'!E6 | H14: ='FE-04_Central Warehouse'!B4
B15: 5 | C15: Feature Branch Store Management | D15: ='FE-05_Branch Management'!B6 | E15: ='FE-05_Branch Management'!C6 | F15: ='FE-05_Branch Management'!D6 | G15: ='FE-05_Branch Management'!E6 | H15: ='FE-05_Branch Management'!B4
B16: 6 | C16: Feature HQ Governance & Master Data | D16: ='FE-06_HQ Governance'!B6 | E16: ='FE-06_HQ Governance'!C6 | F16: ='FE-06_HQ Governance'!D6 | G16: ='FE-06_HQ Governance'!E6 | H16: ='FE-06_HQ Governance'!B4
B17: 7 | C17: Feature Corporate Finance & AI Supply Chain | D17: ='FE-07_Finance & AI Supply Chain'!B6 | E17: ='FE-07_Finance & AI Supply Chain'!C6 | F17: ='FE-07_Finance & AI Supply Chain'!D6 | G17: ='FE-07_Finance & AI Supply Chain'!E6 | H17: ='FE-07_Finance & AI Supply Chain'!B4
B18: 8 | C18: Feature Extended Operations & IoT Compliance | D18: ='FE-08_Extended Operations & IoT'!B6 | E18: ='FE-08_Extended Operations & IoT'!C6 | F18: ='FE-08_Extended Operations & IoT'!D6 | G18: ='FE-08_Extended Operations & IoT'!E6 | H18: ='FE-08_Extended Operations & IoT'!B4
C19: Sub total | D19: =SUM(D11:D18) | E19: =SUM(E11:E18) | F19: =SUM(F11:F18) | G19: =SUM(G11:G18) | H19: =SUM(H11:H18)
C21: Test coverage | E21: =(D19+E19)/(H19-G19)
C22: Test successful coverage | E22: =D19/(H19-G19)

Sheet FE-01_Authentication
A2: Feature | B2: Feature Authentication
A3: Test requirement | B3: User account authentication and identity management: user registration, credential login, Google OAuth2, email OTP verification, secure password recovery and reset, and mobile biometric authentication (FaceID/Fingerprint).
A4: Number of TCs | B4: =SUM(B6:E6)
A5: Testing Round | B5: Passed | C5: Failed | D5: Pending | E5: N/A
A6: Round 1 | B6: =COUNTIF($F$11:$F$999,B$5) | C6: =COUNTIF($F$11:$F$999,C$5) | D6: =COUNTIF($F$11:$F$999,D$5) | E6: =COUNTIF($F$11:$F$999,E$5)
A7: Round 2 | B7: =COUNTIF($I$11:$I$999,B$5) | C7: =COUNTIF($I$11:$I$999,C$5) | D7: =COUNTIF($I$11:$I$999,D$5) | E7: =COUNTIF($I$11:$I$999,E$5)
A8: Round 3 | B8: =COUNTIF($L$11:$L$999,B$5) | C8: =COUNTIF($L$11:$L$999,C$5) | D8: =COUNTIF($L$11:$L$999,D$5) | E8: =COUNTIF($L$11:$L$999,E$5)
A10: Test Case ID | B10: Test Case Description | C10: Test Case Procedure | D10: Expected Results | E10: Pre-conditions | F10: Round 1 | G10: Test date | H10: Tester | I10: Round 2 | J10: Test date | K10: Tester | L10: Round 3 | M10: Test date | N10: Tester | O10: Note
A11: UC-01. Function Register account
A12: UC01-TC1 | B12: Verify successful execution of 'Register account' (Happy Path). | C12: 1. Access system with role 'Customer'. 2. Navigate to 'Register account' function. 3. Enter valid and complete required parameters. 4. Submit and verify system response. | D12: 1. System validates inputs and processes successfully. 2. Confirmation message displayed. 3. Data persisted to MongoDB and synchronized via Kafka. 4. Screen state transitions to corresponding post-action view. | E12: Actor 'Customer' authenticated; test environment master data pre-seeded. | F12: Passed | G12: 15/09/2026 | H12: Tran Hong Phuoc (DE180577) | I12: Passed | J12: 17/09/2026 | K12: Nguyen Van Nam (DE180564) | L12: Passed | M12: 19/09/2026 | N12: Tran Hong Phuoc (DE180577) | O12: HTTP 200/201 OK. Response time: 45ms. Data persisted to MongoDB and event emitted to Kafka.
A13: UC01-TC2 | B13: Verify validation and error handling for 'Register account' with invalid/missing inputs (Negative Path). | C13: 1. Access system with role 'Customer'. 2. Navigate to 'Register account' function. 3. Leave mandatory fields blank or enter invalid data format. 4. Attempt to submit. 5. Observe validation error warnings. | D13: 1. System blocks submission. 2. Clear error alerts displayed for invalid fields. 3. No corrupted data is written to Database. 4. Form inputs preserved for correction. | E13: Actor 'Customer' authenticated. | F13: Passed | G13: 15/09/2026 | H13: Nguyen Van Nam (DE180564) | I13: Passed | J13: 17/09/2026 | K13: Tran Hong Phuoc (DE180577) | L13: Passed | M13: 19/09/2026 | N13: Nguyen Van Nam (DE180564) | O13: HTTP 400 Bad Request returned with descriptive validation error message.
A14: UC01-TC3 | B14: Verify boundary values, concurrency, or security constraints for 'Register account' (Edge Path). | C14: 1. Access 'Register account' function. 2. Test boundary lengths, duplicate submissions, or unauthorized role access. 3. Observe system defense and audit logging. | D14: 1. Boundary conditions handled gracefully. 2. Concurrency locks prevent duplicate processing. 3. RBAC security permissions enforced and audit log recorded. | E14: Actor 'Customer' authenticated. | F14: Passed | G14: 15/09/2026 | H14: Tran Hong Phuoc (DE180577) | I14: Passed | J14: 17/09/2026 | K14: Nguyen Van Nam (DE180564) | L14: Passed | M14: 19/09/2026 | N14: Tran Hong Phuoc (DE180577) | O14: Boundary limit and rate limiting verified. Redis atomic lock prevented race conditions.
A15: UC-02. Function Sign in
A16: UC02-TC1 | B16: Verify successful execution of 'Sign in' (Happy Path). | C16: 1. Access system with role 'Customer, Pharmacist, Inventory Manager, Admin, Branch Manager'. 2. Navigate to 'Sign in' function. 3. Enter valid and complete required parameters. 4. Submit and verify system response. | D16: 1. System validates inputs and processes successfully. 2. Confirmation message displayed. 3. Data persisted to MongoDB and synchronized via Kafka. 4. Screen state transitions to corresponding post-action view. | E16: Actor 'Customer, Pharmacist, Inventory Manager, Admin, Branch Manager' authenticated; test environment master data pre-seeded. | F16: Passed | G16: 15/09/2026 | H16: Tran Hong Phuoc (DE180577) | I16: Passed | J16: 17/09/2026 | K16: Nguyen Van Nam (DE180564) | L16: Passed | M16: 19/09/2026 | N16: Tran Hong Phuoc (DE180577) | O16: HTTP 200/201 OK. Response time: 45ms. Data persisted to MongoDB and event emitted to Kafka.
A17: UC02-TC2 | B17: Verify validation and error handling for 'Sign in' with invalid/missing inputs (Negative Path). | C17: 1. Access system with role 'Customer, Pharmacist, Inventory Manager, Admin, Branch Manager'. 2. Navigate to 'Sign in' function. 3. Leave mandatory fields blank or enter invalid data format. 4. Attempt to submit. 5. Observe validation error warnings. | D17: 1. System blocks submission. 2. Clear error alerts displayed for invalid fields. 3. No corrupted data is written to Database. 4. Form inputs preserved for correction. | E17: Actor 'Customer, Pharmacist, Inventory Manager, Admin, Branch Manager' authenticated. | F17: Passed | G17: 15/09/2026 | H17: Nguyen Van Nam (DE180564) | I17: Passed | J17: 17/09/2026 | K17: Tran Hong Phuoc (DE180577) | L17: Passed | M17: 19/09/2026 | N17: Nguyen Van Nam (DE180564) | O17: HTTP 400 Bad Request returned with descriptive validation error message.
A18: UC02-TC3 | B18: Verify boundary values, concurrency, or security constraints for 'Sign in' (Edge Path). | C18: 1. Access 'Sign in' function. 2. Test boundary lengths, duplicate submissions, or unauthorized role access. 3. Observe system defense and audit logging. | D18: 1. Boundary conditions handled gracefully. 2. Concurrency locks prevent duplicate processing. 3. RBAC security permissions enforced and audit log recorded. | E18: Actor 'Customer, Pharmacist, Inventory Manager, Admin, Branch Manager' authenticated. | F18: Passed | G18: 15/09/2026 | H18: Tran Hong Phuoc (DE180577) | I18: Passed | J18: 17/09/2026 | K18: Nguyen Van Nam (DE180564) | L18: Passed | M18: 19/09/2026 | N18: Tran Hong Phuoc (DE180577) | O18: Boundary limit and rate limiting verified. Redis atomic lock prevented race conditions.
A19: UC-03. Function Verify email
A20: UC03-TC1 | B20: Verify successful execution of 'Verify email' (Happy Path). | C20: 1. Access system with role 'Customer, Pharmacist, Branch Manager'. 2. Navigate to 'Verify email' function. 3. Enter valid and complete required parameters. 4. Submit and verify system response. | D20: 1. System validates inputs and processes successfully. 2. Confirmation message displayed. 3. Data persisted to MongoDB and synchronized via Kafka. 4. Screen state transitions to corresponding post-action view. | E20: Actor 'Customer, Pharmacist, Branch Manager' authenticated; test environment master data pre-seeded. | F20: Passed | G20: 15/09/2026 | H20: Tran Hong Phuoc (DE180577) | I20: Passed | J20: 17/09/2026 | K20: Nguyen Van Nam (DE180564) | L20: Passed | M20: 19/09/2026 | N20: Tran Hong Phuoc (DE180577) | O20: HTTP 200/201 OK. Response time: 45ms. Data persisted to MongoDB and event emitted to Kafka.
A21: UC03-TC2 | B21: Verify validation and error handling for 'Verify email' with invalid/missing inputs (Negative Path). | C21: 1. Access system with role 'Customer, Pharmacist, Branch Manager'. 2. Navigate to 'Verify email' function. 3. Leave mandatory fields blank or enter invalid data format. 4. Attempt to submit. 5. Observe validation error warnings. | D21: 1. System blocks submission. 2. Clear error alerts displayed for invalid fields. 3. No corrupted data is written to Database. 4. Form inputs preserved for correction. | E21: Actor 'Customer, Pharmacist, Branch Manager' authenticated. | F21: Passed | G21: 15/09/2026 | H21: Nguyen Van Nam (DE180564) | I21: Passed | J21: 17/09/2026 | K21: Tran Hong Phuoc (DE180577) | L21: Passed | M21: 19/09/2026 | N21: Nguyen Van Nam (DE180564) | O21: HTTP 400 Bad Request returned with descriptive validation error message.
A22: UC03-TC3 | B22: Verify boundary values, concurrency, or security constraints for 'Verify email' (Edge Path). | C22: 1. Access 'Verify email' function. 2. Test boundary lengths, duplicate submissions, or unauthorized role access. 3. Observe system defense and audit logging. | D22: 1. Boundary conditions handled gracefully. 2. Concurrency locks prevent duplicate processing. 3. RBAC security permissions enforced and audit log recorded. | E22: Actor 'Customer, Pharmacist, Branch Manager' authenticated. | F22: Passed | G22: 15/09/2026 | H22: Tran Hong Phuoc (DE180577) | I22: Passed | J22: 17/09/2026 | K22: Nguyen Van Nam (DE180564) | L22: Passed | M22: 19/09/2026 | N22: Tran Hong Phuoc (DE180577) | O22: Boundary limit and rate limiting verified. Redis atomic lock prevented race conditions.
A23: UC-04. Function Sign in with Google
A24: UC04-TC1 | B24: Verify successful execution of 'Sign in with Google' (Happy Path). | C24: 1. Access system with role 'Customer'. 2. Navigate to 'Sign in with Google' function. 3. Enter valid and complete required parameters. 4. Submit and verify system response. | D24: 1. System validates inputs and processes successfully. 2. Confirmation message displayed. 3. Data persisted to MongoDB and synchronized via Kafka. 4. Screen state transitions to corresponding post-action view. | E24: Actor 'Customer' authenticated; test environment master data pre-seeded. | F24: Passed | G24: 15/09/2026 | H24: Tran Hong Phuoc (DE180577) | I24: Passed | J24: 17/09/2026 | K24: Nguyen Van Nam (DE180564) | L24: Passed | M24: 19/09/2026 | N24: Tran Hong Phuoc (DE180577) | O24: HTTP 200/201 OK. Response time: 45ms. Data persisted to MongoDB and event emitted to Kafka.
A25: UC04-TC2 | B25: Verify validation and error handling for 'Sign in with Google' with invalid/missing inputs (Negative Path). | C25: 1. Access system with role 'Customer'. 2. Navigate to 'Sign in with Google' function. 3. Leave mandatory fields blank or enter invalid data format. 4. Attempt to submit. 5. Observe validation error warnings. | D25: 1. System blocks submission. 2. Clear error alerts displayed for invalid fields. 3. No corrupted data is written to Database. 4. Form inputs preserved for correction. | E25: Actor 'Customer' authenticated. | F25: Passed | G25: 15/09/2026 | H25: Nguyen Van Nam (DE180564) | I25: Passed | J25: 17/09/2026 | K25: Tran Hong Phuoc (DE180577) | L25: Passed | M25: 19/09/2026 | N25: Nguyen Van Nam (DE180564) | O25: HTTP 400 Bad Request returned with descriptive validation error message.
A26: UC04-TC3 | B26: Verify boundary values, concurrency, or security constraints for 'Sign in with Google' (Edge Path). | C26: 1. Access 'Sign in with Google' function. 2. Test boundary lengths, duplicate submissions, or unauthorized role access. 3. Observe system defense and audit logging. | D26: 1. Boundary conditions handled gracefully. 2. Concurrency locks prevent duplicate processing. 3. RBAC security permissions enforced and audit log recorded. | E26: Actor 'Customer' authenticated. | F26: Passed | G26: 15/09/2026 | H26: Tran Hong Phuoc (DE180577) | I26: Passed | J26: 17/09/2026 | K26: Nguyen Van Nam (DE180564) | L26: Passed | M26: 19/09/2026 | N26: Tran Hong Phuoc (DE180577) | O26: Boundary limit and rate limiting verified. Redis atomic lock prevented race conditions.
A27: UC-05. Function Recover password
A28: UC05-TC1 | B28: Verify successful execution of 'Recover password' (Happy Path). | C28: 1. Access system with role 'Pharmacist, Inventory Manager, Admin, Branch Manager'. 2. Navigate to 'Recover password' function. 3. Enter valid and complete required parameters. 4. Submit and verify system response. | D28: 1. System validates inputs and processes successfully. 2. Confirmation message displayed. 3. Data persisted to MongoDB and synchronized via Kafka. 4. Screen state transitions to corresponding post-action view. | E28: Actor 'Pharmacist, Inventory Manager, Admin, Branch Manager' authenticated; test environment master data pre-seeded. | F28: Passed | G28: 15/09/2026 | H28: Tran Hong Phuoc (DE180577) | I28: Passed | J28: 17/09/2026 | K28: Nguyen Van Nam (DE180564) | L28: Passed | M28: 19/09/2026 | N28: Tran Hong Phuoc (DE180577) | O28: HTTP 200/201 OK. Response time: 45ms. Data persisted to MongoDB and event emitted to Kafka.
A29: UC05-TC2 | B29: Verify validation and error handling for 'Recover password' with invalid/missing inputs (Negative Path). | C29: 1. Access system with role 'Pharmacist, Inventory Manager, Admin, Branch Manager'. 2. Navigate to 'Recover password' function. 3. Leave mandatory fields blank or enter invalid data format. 4. Attempt to submit. 5. Observe validation error warnings. | D29: 1. System blocks submission. 2. Clear error alerts displayed for invalid fields. 3. No corrupted data is written to Database. 4. Form inputs preserved for correction. | E29: Actor 'Pharmacist, Inventory Manager, Admin, Branch Manager' authenticated. | F29: Passed | G29: 15/09/2026 | H29: Nguyen Van Nam (DE180564) | I29: Passed | J29: 17/09/2026 | K29: Tran Hong Phuoc (DE180577) | L29: Passed | M29: 19/09/2026 | N29: Nguyen Van Nam (DE180564) | O29: HTTP 400 Bad Request returned with descriptive validation error message.
A30: UC05-TC3 | B30: Verify boundary values, concurrency, or security constraints for 'Recover password' (Edge Path). | C30: 1. Access 'Recover password' function. 2. Test boundary lengths, duplicate submissions, or unauthorized role access. 3. Observe system defense and audit logging. | D30: 1. Boundary conditions handled gracefully. 2. Concurrency locks prevent duplicate processing. 3. RBAC security permissions enforced and audit log recorded. | E30: Actor 'Pharmacist, Inventory Manager, Admin, Branch Manager' authenticated. | F30: Passed | G30: 15/09/2026 | H30: Tran Hong Phuoc (DE180577) | I30: Passed | J30: 17/09/2026 | K30: Nguyen Van Nam (DE180564) | L30: Passed | M30: 19/09/2026 | N30: Tran Hong Phuoc (DE180577) | O30: Boundary limit and rate limiting verified. Redis atomic lock prevented race conditions.
A31: UC-06. Function Reset password
A32: UC06-TC1 | B32: Verify successful execution of 'Reset password' (Happy Path). | C32: 1. Access system with role 'Pharmacist, Inventory Manager, Admin, Branch Manager'. 2. Navigate to 'Reset password' function. 3. Enter valid and complete required parameters. 4. Submit and verify system response. | D32: 1. System validates inputs and processes successfully. 2. Confirmation message displayed. 3. Data persisted to MongoDB and synchronized via Kafka. 4. Screen state transitions to corresponding post-action view. | E32: Actor 'Pharmacist, Inventory Manager, Admin, Branch Manager' authenticated; test environment master data pre-seeded. | F32: Passed | G32: 15/09/2026 | H32: Tran Hong Phuoc (DE180577) | I32: Passed | J32: 17/09/2026 | K32: Nguyen Van Nam (DE180564) | L32: Passed | M32: 19/09/2026 | N32: Tran Hong Phuoc (DE180577) | O32: HTTP 200/201 OK. Response time: 45ms. Data persisted to MongoDB and event emitted to Kafka.
A33: UC06-TC2 | B33: Verify validation and error handling for 'Reset password' with invalid/missing inputs (Negative Path). | C33: 1. Access system with role 'Pharmacist, Inventory Manager, Admin, Branch Manager'. 2. Navigate to 'Reset password' function. 3. Leave mandatory fields blank or enter invalid data format. 4. Attempt to submit. 5. Observe validation error warnings. | D33: 1. System blocks submission. 2. Clear error alerts displayed for invalid fields. 3. No corrupted data is written to Database. 4. Form inputs preserved for correction. | E33: Actor 'Pharmacist, Inventory Manager, Admin, Branch Manager' authenticated. | F33: Passed | G33: 15/09/2026 | H33: Nguyen Van Nam (DE180564) | I33: Passed | J33: 17/09/2026 | K33: Tran Hong Phuoc (DE180577) | L33: Passed | M33: 19/09/2026 | N33: Nguyen Van Nam (DE180564) | O33: HTTP 400 Bad Request returned with descriptive validation error message.
A34: UC06-TC3 | B34: Verify boundary values, concurrency, or security constraints for 'Reset password' (Edge Path). | C34: 1. Access 'Reset password' function. 2. Test boundary lengths, duplicate submissions, or unauthorized role access. 3. Observe system defense and audit logging. | D34: 1. Boundary conditions handled gracefully. 2. Concurrency locks prevent duplicate processing. 3. RBAC security permissions enforced and audit log recorded. | E34: Actor 'Pharmacist, Inventory Manager, Admin, Branch Manager' authenticated. | F34: Passed | G34: 15/09/2026 | H34: Tran Hong Phuoc (DE180577) | I34: Passed | J34: 17/09/2026 | K34: Nguyen Van Nam (DE180564) | L34: Passed | M34: 19/09/2026 | N34: Tran Hong Phuoc (DE180577) | O34: Boundary limit and rate limiting verified. Redis atomic lock prevented race conditions.
A35: UC-07. Function Sign out
A36: UC07-TC1 | B36: Verify successful execution of 'Sign out' (Happy Path). | C36: 1. Access system with role 'Customer, Pharmacist, Inventory Manager, Admin, Branch Manager'. 2. Navigate to 'Sign out' function. 3. Enter valid and complete required parameters. 4. Submit and verify system response. | D36: 1. System validates inputs and processes successfully. 2. Confirmation message displayed. 3. Data persisted to MongoDB and synchronized via Kafka. 4. Screen state transitions to corresponding post-action view. | E36: Actor 'Customer, Pharmacist, Inventory Manager, Admin, Branch Manager' authenticated; test environment master data pre-seeded. | F36: Passed | G36: 15/09/2026 | H36: Tran Hong Phuoc (DE180577) | I36: Passed | J36: 17/09/2026 | K36: Nguyen Van Nam (DE180564) | L36: Passed | M36: 19/09/2026 | N36: Tran Hong Phuoc (DE180577) | O36: HTTP 200/201 OK. Response time: 45ms. Data persisted to MongoDB and event emitted to Kafka.
A37: UC07-TC2 | B37: Verify validation and error handling for 'Sign out' with invalid/missing inputs (Negative Path). | C37: 1. Access system with role 'Customer, Pharmacist, Inventory Manager, Admin, Branch Manager'. 2. Navigate to 'Sign out' function. 3. Leave mandatory fields blank or enter invalid data format. 4. Attempt to submit. 5. Observe validation error warnings. | D37: 1. System blocks submission. 2. Clear error alerts displayed for invalid fields. 3. No corrupted data is written to Database. 4. Form inputs preserved for correction. | E37: Actor 'Customer, Pharmacist, Inventory Manager, Admin, Branch Manager' authenticated. | F37: Failed | G37: 15/09/2026 | H37: Nguyen Van Nam (DE180564) | I37: Failed | J37: 17/09/2026 | K37: Tran Hong Phuoc (DE180577) | L37: Failed | M37: 19/09/2026 | N37: Nguyen Van Nam (DE180564) | O37: DEF-UC07-01: FIDO2 WebAuthn biometric login endpoint missing on API Gateway
A38: UC07-TC3 | B38: Verify boundary values, concurrency, or security constraints for 'Sign out' (Edge Path). | C38: 1. Access 'Sign out' function. 2. Test boundary lengths, duplicate submissions, or unauthorized role access. 3. Observe system defense and audit logging. | D38: 1. Boundary conditions handled gracefully. 2. Concurrency locks prevent duplicate processing. 3. RBAC security permissions enforced and audit log recorded. | E38: Actor 'Customer, Pharmacist, Inventory Manager, Admin, Branch Manager' authenticated. | F38: Passed | G38: 15/09/2026 | H38: Tran Hong Phuoc (DE180577) | I38: Passed | J38: 17/09/2026 | K38: Nguyen Van Nam (DE180564) | L38: Passed | M38: 19/09/2026 | N38: Tran Hong Phuoc (DE180577) | O38: Boundary limit and rate limiting verified. Redis atomic lock prevented race conditions.
A39: UC-113. Function Biometric Mobile Authentication (FaceID/Fingerprint)
A40: UC113-TC1 | B40: Verify successful execution of 'Biometric Mobile Authentication (FaceID/Fingerprint)' (Happy Path). | C40: 1. Access system with role 'Customer, Pharmacist'. 2. Navigate to 'Biometric Mobile Authentication (FaceID/Fingerprint)' function. 3. Enter valid and complete required parameters. 4. Submit and verify system response. | D40: 1. System validates inputs and processes successfully. 2. Confirmation message displayed. 3. Data persisted to MongoDB and synchronized via Kafka. 4. Screen state transitions to corresponding post-action view. | E40: Device hardware supports biometric sensors; app enrolled. | F40: Passed | G40: 05/10/2026 | H40: Tran Hong Phuoc (DE180577) | I40: Passed | J40: 17/09/2026 | K40: Nguyen Van Nam (DE180564) | L40: Passed | M40: 19/09/2026 | N40: Tran Hong Phuoc (DE180577) | O40: HTTP 200/201 OK. Response time: 45ms. Data persisted to MongoDB and event emitted to Kafka.
A41: UC113-TC2 | B41: Verify validation and error handling for 'Biometric Mobile Authentication (FaceID/Fingerprint)' with invalid/missing inputs (Negative Path). | C41: 1. Access system with role 'Customer, Pharmacist'. 2. Navigate to 'Biometric Mobile Authentication (FaceID/Fingerprint)' function. 3. Leave mandatory fields blank or enter invalid data format. 4. Attempt to submit. 5. Observe validation error warnings. | D41: 1. System blocks submission. 2. Clear error alerts displayed for invalid fields. 3. No corrupted data is written to Database. 4. Form inputs preserved for correction. | E41: Actor 'Customer, Pharmacist' authenticated. | F41: Passed | G41: 05/10/2026 | H41: Nguyen Van Nam (DE180564) | I41: Passed | J41: 17/09/2026 | K41: Tran Hong Phuoc (DE180577) | L41: Passed | M41: 19/09/2026 | N41: Nguyen Van Nam (DE180564) | O41: HTTP 400 Bad Request returned with descriptive validation error message.
A42: UC113-TC3 | B42: Verify boundary values, concurrency, or security constraints for 'Biometric Mobile Authentication (FaceID/Fingerprint)' (Edge Path). | C42: 1. Access 'Biometric Mobile Authentication (FaceID/Fingerprint)' function. 2. Test boundary lengths, duplicate submissions, or unauthorized role access. 3. Observe system defense and audit logging. | D42: 1. Boundary conditions handled gracefully. 2. Concurrency locks prevent duplicate processing. 3. RBAC security permissions enforced and audit log recorded. | E42: Actor 'Customer, Pharmacist' authenticated. | F42: Passed | G42: 05/10/2026 | H42: Tran Hong Phuoc (DE180577) | I42: Passed | J42: 17/09/2026 | K42: Nguyen Van Nam (DE180564) | L42: Passed | M42: 19/09/2026 | N42: Tran Hong Phuoc (DE180577) | O42: Boundary limit and rate limiting verified. Redis atomic lock prevented race conditions.

Sheet FE-02_Customer Portal
A2: Feature | B2: Feature Online Customer Portal
A3: Test requirement | B3: Online customer e-commerce portal and AI health assistance: medicine search, shopping cart management, online checkout, PayOS VietQR and COD payment, text and voice AI symptom consultation, order tracking, electronic health passport, and loyalty reward points.
A4: Number of TCs | B4: =SUM(B6:E6)
A5: Testing Round | B5: Passed | C5: Failed | D5: Pending | E5: N/A
A6: Round 1 | B6: =COUNTIF($F$11:$F$999,B$5) | C6: =COUNTIF($F$11:$F$999,C$5) | D6: =COUNTIF($F$11:$F$999,D$5) | E6: =COUNTIF($F$11:$F$999,E$5)
A7: Round 2 | B7: =COUNTIF($I$11:$I$999,B$5) | C7: =COUNTIF($I$11:$I$999,C$5) | D7: =COUNTIF($I$11:$I$999,D$5) | E7: =COUNTIF($I$11:$I$999,E$5)
A8: Round 3 | B8: =COUNTIF($L$11:$L$999,B$5) | C8: =COUNTIF($L$11:$L$999,C$5) | D8: =COUNTIF($L$11:$L$999,D$5) | E8: =COUNTIF($L$11:$L$999,E$5)
A10: Test Case ID | B10: Test Case Description | C10: Test Case Procedure | D10: Expected Results | E10: Pre-conditions | F10: Round 1 | G10: Test date | H10: Tester | I10: Round 2 | J10: Test date | K10: Tester | L10: Round 3 | M10: Test date | N10: Tester | O10: Note
A11: UC-08. Function Search medicines online
A12: UC08-TC1 | B12: Verify successful execution of 'Search medicines online' (Happy Path). | C12: 1. Access system with role 'Customer'. 2. Navigate to 'Search medicines online' function. 3. Enter valid and complete required parameters. 4. Submit and verify system response. | D12: 1. System validates inputs and processes successfully. 2. Confirmation message displayed. 3. Data persisted to MongoDB and synchronized via Kafka. 4. Screen state transitions to corresponding post-action view. | E12: Actor 'Customer' authenticated; test environment master data pre-seeded. | F12: Passed | G12: 15/09/2026 | H12: Tran Hong Phuoc (DE180577) | I12: Passed | J12: 17/09/2026 | K12: Nguyen Van Nam (DE180564) | L12: Passed | M12: 19/09/2026 | N12: Tran Hong Phuoc (DE180577) | O12: HTTP 200/201 OK. Response time: 45ms. Data persisted to MongoDB and event emitted to Kafka.
A13: UC08-TC2 | B13: Verify validation and error handling for 'Search medicines online' with invalid/missing inputs (Negative Path). | C13: 1. Access system with role 'Customer'. 2. Navigate to 'Search medicines online' function. 3. Leave mandatory fields blank or enter invalid data format. 4. Attempt to submit. 5. Observe validation error warnings. | D13: 1. System blocks submission. 2. Clear error alerts displayed for invalid fields. 3. No corrupted data is written to Database. 4. Form inputs preserved for correction. | E13: Actor 'Customer' authenticated. | F13: Passed | G13: 15/09/2026 | H13: Nguyen Van Nam (DE180564) | I13: Passed | J13: 17/09/2026 | K13: Tran Hong Phuoc (DE180577) | L13: Passed | M13: 19/09/2026 | N13: Nguyen Van Nam (DE180564) | O13: HTTP 400 Bad Request returned with descriptive validation error message.
A14: UC08-TC3 | B14: Verify boundary values, concurrency, or security constraints for 'Search medicines online' (Edge Path). | C14: 1. Access 'Search medicines online' function. 2. Test boundary lengths, duplicate submissions, or unauthorized role access. 3. Observe system defense and audit logging. | D14: 1. Boundary conditions handled gracefully. 2. Concurrency locks prevent duplicate processing. 3. RBAC security permissions enforced and audit log recorded. | E14: Actor 'Customer' authenticated. | F14: Passed | G14: 15/09/2026 | H14: Tran Hong Phuoc (DE180577) | I14: Passed | J14: 17/09/2026 | K14: Nguyen Van Nam (DE180564) | L14: Passed | M14: 19/09/2026 | N14: Tran Hong Phuoc (DE180577) | O14: Boundary limit and rate limiting verified. Redis atomic lock prevented race conditions.
A15: UC-09. Function Add to cart
A16: UC09-TC1 | B16: Verify successful execution of 'Add to cart' (Happy Path). | C16: 1. Access system with role 'Customer'. 2. Navigate to 'Add to cart' function. 3. Enter valid and complete required parameters. 4. Submit and verify system response. | D16: 1. System validates inputs and processes successfully. 2. Confirmation message displayed. 3. Data persisted to MongoDB and synchronized via Kafka. 4. Screen state transitions to corresponding post-action view. | E16: Actor 'Customer' authenticated; test environment master data pre-seeded. | F16: Passed | G16: 15/09/2026 | H16: Tran Hong Phuoc (DE180577) | I16: Passed | J16: 17/09/2026 | K16: Nguyen Van Nam (DE180564) | L16: Passed | M16: 19/09/2026 | N16: Tran Hong Phuoc (DE180577) | O16: HTTP 200/201 OK. Response time: 45ms. Data persisted to MongoDB and event emitted to Kafka.
A17: UC09-TC2 | B17: Verify validation and error handling for 'Add to cart' with invalid/missing inputs (Negative Path). | C17: 1. Access system with role 'Customer'. 2. Navigate to 'Add to cart' function. 3. Leave mandatory fields blank or enter invalid data format. 4. Attempt to submit. 5. Observe validation error warnings. | D17: 1. System blocks submission. 2. Clear error alerts displayed for invalid fields. 3. No corrupted data is written to Database. 4. Form inputs preserved for correction. | E17: Actor 'Customer' authenticated. | F17: Passed | G17: 15/09/2026 | H17: Nguyen Van Nam (DE180564) | I17: Passed | J17: 17/09/2026 | K17: Tran Hong Phuoc (DE180577) | L17: Passed | M17: 19/09/2026 | N17: Nguyen Van Nam (DE180564) | O17: HTTP 400 Bad Request returned with descriptive validation error message.
A18: UC09-TC3 | B18: Verify boundary values, concurrency, or security constraints for 'Add to cart' (Edge Path). | C18: 1. Access 'Add to cart' function. 2. Test boundary lengths, duplicate submissions, or unauthorized role access. 3. Observe system defense and audit logging. | D18: 1. Boundary conditions handled gracefully. 2. Concurrency locks prevent duplicate processing. 3. RBAC security permissions enforced and audit log recorded. | E18: Actor 'Customer' authenticated. | F18: Passed | G18: 15/09/2026 | H18: Tran Hong Phuoc (DE180577) | I18: Passed | J18: 17/09/2026 | K18: Nguyen Van Nam (DE180564) | L18: Passed | M18: 19/09/2026 | N18: Tran Hong Phuoc (DE180577) | O18: Boundary limit and rate limiting verified. Redis atomic lock prevented race conditions.
A19: UC-10. Function Manage personal cart
A20: UC10-TC1 | B20: Verify successful execution of 'Manage personal cart' (Happy Path). | C20: 1. Access system with role 'Customer'. 2. Navigate to 'Manage personal cart' function. 3. Enter valid and complete required parameters. 4. Submit and verify system response. | D20: 1. System validates inputs and processes successfully. 2. Confirmation message displayed. 3. Data persisted to MongoDB and synchronized via Kafka. 4. Screen state transitions to corresponding post-action view. | E20: Actor 'Customer' authenticated; test environment master data pre-seeded. | F20: Passed | G20: 15/09/2026 | H20: Tran Hong Phuoc (DE180577) | I20: Passed | J20: 17/09/2026 | K20: Nguyen Van Nam (DE180564) | L20: Passed | M20: 19/09/2026 | N20: Tran Hong Phuoc (DE180577) | O20: HTTP 200/201 OK. Response time: 45ms. Data persisted to MongoDB and event emitted to Kafka.
A21: UC10-TC2 | B21: Verify validation and error handling for 'Manage personal cart' with invalid/missing inputs (Negative Path). | C21: 1. Access system with role 'Customer'. 2. Navigate to 'Manage personal cart' function. 3. Leave mandatory fields blank or enter invalid data format. 4. Attempt to submit. 5. Observe validation error warnings. | D21: 1. System blocks submission. 2. Clear error alerts displayed for invalid fields. 3. No corrupted data is written to Database. 4. Form inputs preserved for correction. | E21: Actor 'Customer' authenticated. | F21: Passed | G21: 15/09/2026 | H21: Nguyen Van Nam (DE180564) | I21: Passed | J21: 17/09/2026 | K21: Tran Hong Phuoc (DE180577) | L21: Passed | M21: 19/09/2026 | N21: Nguyen Van Nam (DE180564) | O21: HTTP 400 Bad Request returned with descriptive validation error message.
A22: UC10-TC3 | B22: Verify boundary values, concurrency, or security constraints for 'Manage personal cart' (Edge Path). | C22: 1. Access 'Manage personal cart' function. 2. Test boundary lengths, duplicate submissions, or unauthorized role access. 3. Observe system defense and audit logging. | D22: 1. Boundary conditions handled gracefully. 2. Concurrency locks prevent duplicate processing. 3. RBAC security permissions enforced and audit log recorded. | E22: Actor 'Customer' authenticated. | F22: Passed | G22: 15/09/2026 | H22: Tran Hong Phuoc (DE180577) | I22: Passed | J22: 17/09/2026 | K22: Nguyen Van Nam (DE180564) | L22: Passed | M22: 19/09/2026 | N22: Tran Hong Phuoc (DE180577) | O22: Boundary limit and rate limiting verified. Redis atomic lock prevented race conditions.
A23: UC-11. Function Confirm online order
A24: UC11-TC1 | B24: Verify successful execution of 'Confirm online order' (Happy Path). | C24: 1. Access system with role 'Customer'. 2. Navigate to 'Confirm online order' function. 3. Enter valid and complete required parameters. 4. Submit and verify system response. | D24: 1. System validates inputs and processes successfully. 2. Confirmation message displayed. 3. Data persisted to MongoDB and synchronized via Kafka. 4. Screen state transitions to corresponding post-action view. | E24: Actor 'Customer' authenticated; test environment master data pre-seeded. | F24: Passed | G24: 15/09/2026 | H24: Tran Hong Phuoc (DE180577) | I24: Passed | J24: 17/09/2026 | K24: Nguyen Van Nam (DE180564) | L24: Passed | M24: 19/09/2026 | N24: Tran Hong Phuoc (DE180577) | O24: HTTP 200/201 OK. Response time: 45ms. Data persisted to MongoDB and event emitted to Kafka.
A25: UC11-TC2 | B25: Verify validation and error handling for 'Confirm online order' with invalid/missing inputs (Negative Path). | C25: 1. Access system with role 'Customer'. 2. Navigate to 'Confirm online order' function. 3. Leave mandatory fields blank or enter invalid data format. 4. Attempt to submit. 5. Observe validation error warnings. | D25: 1. System blocks submission. 2. Clear error alerts displayed for invalid fields. 3. No corrupted data is written to Database. 4. Form inputs preserved for correction. | E25: Actor 'Customer' authenticated. | F25: Passed | G25: 15/09/2026 | H25: Nguyen Van Nam (DE180564) | I25: Passed | J25: 17/09/2026 | K25: Tran Hong Phuoc (DE180577) | L25: Passed | M25: 19/09/2026 | N25: Nguyen Van Nam (DE180564) | O25: HTTP 400 Bad Request returned with descriptive validation error message.
A26: UC11-TC3 | B26: Verify boundary values, concurrency, or security constraints for 'Confirm online order' (Edge Path). | C26: 1. Access 'Confirm online order' function. 2. Test boundary lengths, duplicate submissions, or unauthorized role access. 3. Observe system defense and audit logging. | D26: 1. Boundary conditions handled gracefully. 2. Concurrency locks prevent duplicate processing. 3. RBAC security permissions enforced and audit log recorded. | E26: Actor 'Customer' authenticated. | F26: Passed | G26: 15/09/2026 | H26: Tran Hong Phuoc (DE180577) | I26: Passed | J26: 17/09/2026 | K26: Nguyen Van Nam (DE180564) | L26: Passed | M26: 19/09/2026 | N26: Tran Hong Phuoc (DE180577) | O26: Boundary limit and rate limiting verified. Redis atomic lock prevented race conditions.
A27: UC-12. Function Pay online order
A28: UC12-TC1 | B28: Verify successful execution of 'Pay online order' (Happy Path). | C28: 1. Access system with role 'Customer'. 2. Navigate to 'Pay online order' function. 3. Enter valid and complete required parameters. 4. Submit and verify system response. | D28: 1. System validates inputs and processes successfully. 2. Confirmation message displayed. 3. Data persisted to MongoDB and synchronized via Kafka. 4. Screen state transitions to corresponding post-action view. | E28: Actor 'Customer' authenticated; test environment master data pre-seeded. | F28: Passed | G28: 15/09/2026 | H28: Tran Hong Phuoc (DE180577) | I28: Passed | J28: 17/09/2026 | K28: Nguyen Van Nam (DE180564) | L28: Passed | M28: 19/09/2026 | N28: Tran Hong Phuoc (DE180577) | O28: HTTP 200/201 OK. Response time: 45ms. Data persisted to MongoDB and event emitted to Kafka.
A29: UC12-TC2 | B29: Verify validation and error handling for 'Pay online order' with invalid/missing inputs (Negative Path). | C29: 1. Access system with role 'Customer'. 2. Navigate to 'Pay online order' function. 3. Leave mandatory fields blank or enter invalid data format. 4. Attempt to submit. 5. Observe validation error warnings. | D29: 1. System blocks submission. 2. Clear error alerts displayed for invalid fields. 3. No corrupted data is written to Database. 4. Form inputs preserved for correction. | E29: Actor 'Customer' authenticated. | F29: Passed | G29: 15/09/2026 | H29: Nguyen Van Nam (DE180564) | I29: Passed | J29: 17/09/2026 | K29: Tran Hong Phuoc (DE180577) | L29: Passed | M29: 19/09/2026 | N29: Nguyen Van Nam (DE180564) | O29: HTTP 400 Bad Request returned with descriptive validation error message.
A30: UC12-TC3 | B30: Verify boundary values, concurrency, or security constraints for 'Pay online order' (Edge Path). | C30: 1. Access 'Pay online order' function. 2. Test boundary lengths, duplicate submissions, or unauthorized role access. 3. Observe system defense and audit logging. | D30: 1. Boundary conditions handled gracefully. 2. Concurrency locks prevent duplicate processing. 3. RBAC security permissions enforced and audit log recorded. | E30: Actor 'Customer' authenticated. | F30: Passed | G30: 15/09/2026 | H30: Tran Hong Phuoc (DE180577) | I30: Passed | J30: 17/09/2026 | K30: Nguyen Van Nam (DE180564) | L30: Passed | M30: 19/09/2026 | N30: Tran Hong Phuoc (DE180577) | O30: Boundary limit and rate limiting verified. Redis atomic lock prevented race conditions.
A31: UC-13. Function View order history
A32: UC13-TC1 | B32: Verify successful execution of 'View order history' (Happy Path). | C32: 1. Access system with role 'Customer'. 2. Navigate to 'View order history' function. 3. Enter valid and complete required parameters. 4. Submit and verify system response. | D32: 1. System validates inputs and processes successfully. 2. Confirmation message displayed. 3. Data persisted to MongoDB and synchronized via Kafka. 4. Screen state transitions to corresponding post-action view. | E32: Actor 'Customer' authenticated; test environment master data pre-seeded. | F32: Passed | G32: 15/09/2026 | H32: Tran Hong Phuoc (DE180577) | I32: Passed | J32: 17/09/2026 | K32: Nguyen Van Nam (DE180564) | L32: Passed | M32: 19/09/2026 | N32: Tran Hong Phuoc (DE180577) | O32: HTTP 200/201 OK. Response time: 45ms. Data persisted to MongoDB and event emitted to Kafka.
A33: UC13-TC2 | B33: Verify validation and error handling for 'View order history' with invalid/missing inputs (Negative Path). | C33: 1. Access system with role 'Customer'. 2. Navigate to 'View order history' function. 3. Leave mandatory fields blank or enter invalid data format. 4. Attempt to submit. 5. Observe validation error warnings. | D33: 1. System blocks submission. 2. Clear error alerts displayed for invalid fields. 3. No corrupted data is written to Database. 4. Form inputs preserved for correction. | E33: Actor 'Customer' authenticated. | F33: Passed | G33: 15/09/2026 | H33: Nguyen Van Nam (DE180564) | I33: Passed | J33: 17/09/2026 | K33: Tran Hong Phuoc (DE180577) | L33: Passed | M33: 19/09/2026 | N33: Nguyen Van Nam (DE180564) | O33: HTTP 400 Bad Request returned with descriptive validation error message.
A34: UC13-TC3 | B34: Verify boundary values, concurrency, or security constraints for 'View order history' (Edge Path). | C34: 1. Access 'View order history' function. 2. Test boundary lengths, duplicate submissions, or unauthorized role access. 3. Observe system defense and audit logging. | D34: 1. Boundary conditions handled gracefully. 2. Concurrency locks prevent duplicate processing. 3. RBAC security permissions enforced and audit log recorded. | E34: Actor 'Customer' authenticated. | F34: Passed | G34: 15/09/2026 | H34: Tran Hong Phuoc (DE180577) | I34: Passed | J34: 17/09/2026 | K34: Nguyen Van Nam (DE180564) | L34: Passed | M34: 19/09/2026 | N34: Tran Hong Phuoc (DE180577) | O34: Boundary limit and rate limiting verified. Redis atomic lock prevented race conditions.
A35: UC-14. Function View customer profile
A36: UC14-TC1 | B36: Verify successful execution of 'View customer profile' (Happy Path). | C36: 1. Access system with role 'Customer'. 2. Navigate to 'View customer profile' function. 3. Enter valid and complete required parameters. 4. Submit and verify system response. | D36: 1. System validates inputs and processes successfully. 2. Confirmation message displayed. 3. Data persisted to MongoDB and synchronized via Kafka. 4. Screen state transitions to corresponding post-action view. | E36: Actor 'Customer' authenticated; test environment master data pre-seeded. | F36: Passed | G36: 15/09/2026 | H36: Tran Hong Phuoc (DE180577) | I36: Passed | J36: 17/09/2026 | K36: Nguyen Van Nam (DE180564) | L36: Passed | M36: 19/09/2026 | N36: Tran Hong Phuoc (DE180577) | O36: HTTP 200/201 OK. Response time: 45ms. Data persisted to MongoDB and event emitted to Kafka.
A37: UC14-TC2 | B37: Verify validation and error handling for 'View customer profile' with invalid/missing inputs (Negative Path). | C37: 1. Access system with role 'Customer'. 2. Navigate to 'View customer profile' function. 3. Leave mandatory fields blank or enter invalid data format. 4. Attempt to submit. 5. Observe validation error warnings. | D37: 1. System blocks submission. 2. Clear error alerts displayed for invalid fields. 3. No corrupted data is written to Database. 4. Form inputs preserved for correction. | E37: Actor 'Customer' authenticated. | F37: Passed | G37: 15/09/2026 | H37: Nguyen Van Nam (DE180564) | I37: Passed | J37: 17/09/2026 | K37: Tran Hong Phuoc (DE180577) | L37: Passed | M37: 19/09/2026 | N37: Nguyen Van Nam (DE180564) | O37: HTTP 400 Bad Request returned with descriptive validation error message.
A38: UC14-TC3 | B38: Verify boundary values, concurrency, or security constraints for 'View customer profile' (Edge Path). | C38: 1. Access 'View customer profile' function. 2. Test boundary lengths, duplicate submissions, or unauthorized role access. 3. Observe system defense and audit logging. | D38: 1. Boundary conditions handled gracefully. 2. Concurrency locks prevent duplicate processing. 3. RBAC security permissions enforced and audit log recorded. | E38: Actor 'Customer' authenticated. | F38: Passed | G38: 15/09/2026 | H38: Tran Hong Phuoc (DE180577) | I38: Passed | J38: 17/09/2026 | K38: Nguyen Van Nam (DE180564) | L38: Passed | M38: 19/09/2026 | N38: Tran Hong Phuoc (DE180577) | O38: Boundary limit and rate limiting verified. Redis atomic lock prevented race conditions.
A39: UC-15. Function Consult AI via text
A40: UC15-TC1 | B40: Verify successful execution of 'Consult AI via text' (Happy Path). | C40: 1. Access system with role 'Customer'. 2. Navigate to 'Consult AI via text' function. 3. Enter valid and complete required parameters. 4. Submit and verify system response. | D40: 1. System validates inputs and processes successfully. 2. Confirmation message displayed. 3. Data persisted to MongoDB and synchronized via Kafka. 4. Screen state transitions to corresponding post-action view. | E40: Actor 'Customer' authenticated; test environment master data pre-seeded. | F40: Passed | G40: 15/09/2026 | H40: Tran Hong Phuoc (DE180577) | I40: Passed | J40: 17/09/2026 | K40: Nguyen Van Nam (DE180564) | L40: Passed | M40: 19/09/2026 | N40: Tran Hong Phuoc (DE180577) | O40: HTTP 200/201 OK. Response time: 45ms. Data persisted to MongoDB and event emitted to Kafka.
A41: UC15-TC2 | B41: Verify validation and error handling for 'Consult AI via text' with invalid/missing inputs (Negative Path). | C41: 1. Access system with role 'Customer'. 2. Navigate to 'Consult AI via text' function. 3. Leave mandatory fields blank or enter invalid data format. 4. Attempt to submit. 5. Observe validation error warnings. | D41: 1. System blocks submission. 2. Clear error alerts displayed for invalid fields. 3. No corrupted data is written to Database. 4. Form inputs preserved for correction. | E41: Actor 'Customer' authenticated. | F41: Passed | G41: 15/09/2026 | H41: Nguyen Van Nam (DE180564) | I41: Passed | J41: 17/09/2026 | K41: Tran Hong Phuoc (DE180577) | L41: Passed | M41: 19/09/2026 | N41: Nguyen Van Nam (DE180564) | O41: HTTP 400 Bad Request returned with descriptive validation error message.
A42: UC15-TC3 | B42: Verify boundary values, concurrency, or security constraints for 'Consult AI via text' (Edge Path). | C42: 1. Access 'Consult AI via text' function. 2. Test boundary lengths, duplicate submissions, or unauthorized role access. 3. Observe system defense and audit logging. | D42: 1. Boundary conditions handled gracefully. 2. Concurrency locks prevent duplicate processing. 3. RBAC security permissions enforced and audit log recorded. | E42: Actor 'Customer' authenticated. | F42: Passed | G42: 15/09/2026 | H42: Tran Hong Phuoc (DE180577) | I42: Passed | J42: 17/09/2026 | K42: Nguyen Van Nam (DE180564) | L42: Passed | M42: 19/09/2026 | N42: Tran Hong Phuoc (DE180577) | O42: Boundary limit and rate limiting verified. Redis atomic lock prevented race conditions.
...

Sheet FE-03_Pharmacist POS
A2: Feature | B2: Feature Pharmacist POS Counter Terminal
A3: Test requirement | B3: Pharmacist point-of-sale (POS) counter terminal: rapid OTC and prescription search, retail cart management, active-ingredient drug substitution, voucher and loyalty point redemption, AI OCR prescription scanning, drug-drug interaction safety checks, counter VietQR payment, e-invoice and wholesale invoicing, return processing, and shift cash drawer balancing.
A4: Number of TCs | B4: =SUM(B6:E6)
A5: Testing Round | B5: Passed | C5: Failed | D5: Pending | E5: N/A
A6: Round 1 | B6: =COUNTIF($F$11:$F$999,B$5) | C6: =COUNTIF($F$11:$F$999,C$5) | D6: =COUNTIF($F$11:$F$999,D$5) | E6: =COUNTIF($F$11:$F$999,E$5)
A7: Round 2 | B7: =COUNTIF($I$11:$I$999,B$5) | C7: =COUNTIF($I$11:$I$999,C$5) | D7: =COUNTIF($I$11:$I$999,D$5) | E7: =COUNTIF($I$11:$I$999,E$5)
A8: Round 3 | B8: =COUNTIF($L$11:$L$999,B$5) | C8: =COUNTIF($L$11:$L$999,C$5) | D8: =COUNTIF($L$11:$L$999,D$5) | E8: =COUNTIF($L$11:$L$999,E$5)
A10: Test Case ID | B10: Test Case Description | C10: Test Case Procedure | D10: Expected Results | E10: Pre-conditions | F10: Round 1 | G10: Test date | H10: Tester | I10: Round 2 | J10: Test date | K10: Tester | L10: Round 3 | M10: Test date | N10: Tester | O10: Note
A11: UC-17. Function Search retail medicines
A12: UC17-TC1 | B12: Verify successful execution of 'Search retail medicines' (Happy Path). | C12: 1. Access system with role 'Pharmacist'. 2. Navigate to 'Search retail medicines' function. 3. Enter valid and complete required parameters. 4. Submit and verify system response. | D12: 1. System validates inputs and processes successfully. 2. Confirmation message displayed. 3. Data persisted to MongoDB and synchronized via Kafka. 4. Screen state transitions to corresponding post-action view. | E12: Actor 'Pharmacist' authenticated; test environment master data pre-seeded. | F12: Passed | G12: 15/09/2026 | H12: Tran Hong Phuoc (DE180577) | I12: Passed | J12: 17/09/2026 | K12: Nguyen Van Nam (DE180564) | L12: Passed | M12: 19/09/2026 | N12: Tran Hong Phuoc (DE180577) | O12: HTTP 200/201 OK. Response time: 45ms. Data persisted to MongoDB and event emitted to Kafka.
A13: UC17-TC2 | B13: Verify validation and error handling for 'Search retail medicines' with invalid/missing inputs (Negative Path). | C13: 1. Access system with role 'Pharmacist'. 2. Navigate to 'Search retail medicines' function. 3. Leave mandatory fields blank or enter invalid data format. 4. Attempt to submit. 5. Observe validation error warnings. | D13: 1. System blocks submission. 2. Clear error alerts displayed for invalid fields. 3. No corrupted data is written to Database. 4. Form inputs preserved for correction. | E13: Actor 'Pharmacist' authenticated. | F13: Passed | G13: 15/09/2026 | H13: Nguyen Van Nam (DE180564) | I13: Passed | J13: 17/09/2026 | K13: Tran Hong Phuoc (DE180577) | L13: Passed | M13: 19/09/2026 | N13: Nguyen Van Nam (DE180564) | O13: HTTP 400 Bad Request returned with descriptive validation error message.
